Workbook

Sheet خروف ملحمه
A1: يوم 13-07-2026
A3: السعر | B3: الاجمالي | C3: الخروف | D3: عدد الخرفان | F3: السعر كيلو ( الفاتورة ) | G3: اجمالي السعر
D4: 3 | F4: 10.011167 | G4: =F4*G12 -> 547.10025 | K4: 10 | L4: 10.227
C5: اسم الصنف | G5: الكمية | K5: 10 | L5: 10.25
A6: =B6*G6 -> 4.6 | B6: 1 | C6: نتر | G6: 4.6 | H6: 5430 | K6: 11 | L6: 10.295
A7: =B7*G7 -> 7 | B7: 10 | C7: زوايد حمراء | G7: 0.7 | H7: لا يوجد | K7: 11 | L7: 10.25
A8: =B8*G8 -> 0 | B8: 5 | C8: لية | G8: 0 | H8: 4598 | K8: 12 | L8: 10.095
A9: =B9*G9 -> 4 | B9: 5 | C9: سقط | G9: 0.8 | H9: لا يوجد | K9: 12 | L9: 10.417
A10: =G4-A9-A8-A7-A6 -> 531.50025 | B10: =A10/G10 -> 11.09627 | C10: لحم صافي | G10: 47.899 | H10: 5434-M | I10: 4608-M | J10: 4943-M | K10: 13 | L10: 10.213
A11: =B11*G11 -> 0 | B11: 0 | C11: هدر | G11: 0.65 | K11: 13 | L11: 10.162
A12: الاجمالي | C12: الوزن عند استلام ( الفاتورة ) | G12: =SUM(G6:G11) -> 54.649 | K12: 13 | L12: 9.336
K13: 14 | L13: 10.25
K14: 14 | L14: 9.774
C15: الفاقد | G15: =G12-G16 -> 0.65 | K15: 15 | L15: 10.208
A16: =SUM(A6:A11) -> 547.10025 | C16: صافي الوزن بعد التقطيع | G16: =SUM(G6:G10) -> 53.999 | K16: 15 | L16: 9.987
K17: 16 | L17: 9.85
K18: 16 | L18: 10.11
K19: 16 | L19: 10.343
A20: 11.653991 | B20: 12.044482 | C20: 12.15685 | K20: 17 | L20: 9.803
A21: =A20+B20+C20 -> 35.855323 | F21: 14 | G21: 11.34736 | K21: 17 | L21: 9.85 | M21: =L21+L20 -> 19.653 | N21: =M21/2 -> 9.8265
A22: =A21/3 -> 11.951774 | F22: 15 | G22: 11.096657 | K22: 18 | L22: 9.823 | M22: =L22+L23 -> 19.673 | N22: =M22/2 -> 9.8365
F23: 17 | G23: 10.59535 | K23: 18 | L23: 9.85
F24: 18 | G24: 10.871601 | K24: 19 | L24: 9.778 | M24: =L24+L25 -> 19.508 | N24: =M24/2 -> 9.754
F25: 19 | G25: 10.674132 | K25: 19 | L25: 9.73
G26: =SUM(G21:G25) -> 54.585099 | K26: 20 | L26: 9.817
G27: =G26/5 -> 10.91702 | K27: 20 | L27: 9.85
L28: =AVERAGE(L4:L27) -> 10.011167

Sheet All Menu
A1: odoo | B1: الكود | C1: Main Group | D1: Sub Group | E1: Menu Item Name | F1: Tax % | G1: Markaziya Price | H1: Sold Qty | I1: AVG Price | J1: تكلفة الصنف | K1: هامش الربح | L1: نسبة التكلفة | M1: نسبة هامش الربح | N1: ملاحظات
A2: FP40100047 | B2: 60069 | C2: قسم التواصي | D2: تجهيزات | E2: دوالي ني | F2: 0 | G2: 11.99 | H2: =SUMIF('Sales 6.2026'!B:F,'All Menu'!B2,'Sales 6.2026'!F:F) -> 0 | J2: =SUMIF('Finished Recipe'!B:B, B2, 'Finished Recipe'!M:M) -> 6.7135998 | K2: =G2-J2 -> 5.2764002 | L2: =J2/G2 -> 0.55993326 | M2: =K2/G2 -> 0.44006674
A3: SR60000002 | B3: SRV-001 | C3: قسم التواصي | D3: خدمات | E3: خدمة توصيل | F3: 0.16 | G3: 0.86206897 | H3: =SUMIF('Sales 6.2026'!B:F,'All Menu'!B3,'Sales 6.2026'!F:F) -> 11 | J3: 0.5 | K3: =G3-J3 -> 0.36206897 | L3: =J3/G3 -> 0.58 | M3: =K3/G3 -> 0.42
A4: SR60000003 | B4: SRV-002 | C4: قسم التواصي | D4: خدمات | E4: أجور | F4: 0.16 | G4: 0.86206897 | H4: =SUMIF('Sales 6.2026'!B:F,'All Menu'!B4,'Sales 6.2026'!F:F) -> 2491.545 | J4: 0.5 | K4: =G4-J4 -> 0.36206897 | L4: =J4/G4 -> 0.58 | M4: =K4/G4 -> 0.42
A5: FP40100001 | B5: TA-ORD-001 | C5: قسم التواصي | D5: التواصي سفري | E5: منسف لحمة / كيلو | F5: 0.16 | G5: 19.827586 | H5: =SUMIF('Sales 6.2026'!B:F,'All Menu'!B5,'Sales 6.2026'!F:F) -> 224.5 | J5: =SUMIF('Finished Recipe'!B:B, B5, 'Finished Recipe'!M:M) -> 13.950858 | K5: =G5-J5 -> 5.8767287 | L5: =J5/G5 -> 0.70360847 | M5: =K5/G5 -> 0.29639153
A6: FP40100002 | B6: TA-ORD-002 | C6: قسم التواصي | D6: التواصي سفري | E6: قدرة لحم 1 كيلو | F6: 0.16 | G6: 19.827586 | H6: =SUMIF('Sales 6.2026'!B:F,'All Menu'!B6,'Sales 6.2026'!F:F) -> 12.0001 | J6: =SUMIF('Finished Recipe'!B:B, B6, 'Finished Recipe'!M:M) -> 13.757562 | K6: =G6-J6 -> 6.0700244 | L6: =J6/G6 -> 0.69385964 | M6: =K6/G6 -> 0.30614036
A7: FP40100003 | B7: TA-ORD-003 | C7: قسم التواصي | D7: التواصي سفري | E7: كبسة لحم 1 كيلو | F7: 0.16 | G7: 19.827586 | H7: =SUMIF('Sales 6.2026'!B:F,'All Menu'!B7,'Sales 6.2026'!F:F) -> 9.001 | J7: =SUMIF('Finished Recipe'!B:B, B7, 'Finished Recipe'!M:M) -> 14.043503 | K7: =G7-J7 -> 5.7840835 | L7: =J7/G7 -> 0.70828101 | M7: =K7/G7 -> 0.29171899
A8: FP40100004 | B8: TA-ORD-004 | C8: قسم التواصي | D8: التواصي سفري | E8: أوزي لحم 1 كيلو | F8: 0.16 | G8: 19.827586 | H8: =SUMIF('Sales 6.2026'!B:F,'All Menu'!B8,'Sales 6.2026'!F:F) -> 24.5 | J8: =SUMIF('Finished Recipe'!B:B, B8, 'Finished Recipe'!M:M) -> 14.851072 | K8: =G8-J8 -> 4.9765143 | L8: =J8/G8 -> 0.74901058 | M8: =K8/G8 -> 0.25098942
A9: FP40100005 | B9: TA-ORD-006 | C9: قسم التواصي | D9: التواصي سفري | E9: فريكة لحم 1 كيلو | F9: 0.16 | G9: 19.827586 | H9: =SUMIF('Sales 6.2026'!B:F,'All Menu'!B9,'Sales 6.2026'!F:F) -> 2 | J9: =SUMIF('Finished Recipe'!B:B, B9, 'Finished Recipe'!M:M) -> 15.034865 | K9: =G9-J9 -> 4.7927208 | L9: =J9/G9 -> 0.75828017 | M9: =K9/G9 -> 0.24171983
A10: FP40100006 | B10: TA-ORD-007 | C10: قسم التواصي | D10: التواصي سفري | E10: زربيان لحم 1 كيلو | F10: 0.16 | G10: 19.827586 | H10: =SUMIF('Sales 6.2026'!B:F,'All Menu'!B10,'Sales 6.2026'!F:F) -> 4 | J10: =SUMIF('Finished Recipe'!B:B, B10, 'Finished Recipe'!M:M) -> 13.566722 | K10: =G10-J10 -> 6.2608645 | L10: =J10/G10 -> 0.68423466 | M10: =K10/G10 -> 0.31576534
A11: FP40100007 | B11: TA-ORD-010 | C11: قسم التواصي | D11: التواصي سفري | E11: زرب لحم 1 كيلو | F11: 0.16 | G11: 19.827586 | H11: =SUMIF('Sales 6.2026'!B:F,'All Menu'!B11,'Sales 6.2026'!F:F) -> 58 | J11: =SUMIF('Finished Recipe'!B:B, B11, 'Finished Recipe'!M:M) -> 13.546738 | K11: =G11-J11 -> 6.2808479 | L11: =J11/G11 -> 0.6832268 | M11: =K11/G11 -> 0.3167732
A12: FP40100008 | B12: TA-ORD-011 | C12: قسم التواصي | D12: التواصي سفري | E12: مندي لحم 1 كيلو | F12: 0.16 | G12: 19.827586 | H12: =SUMIF('Sales 6.2026'!B:F,'All Menu'!B12,'Sales 6.2026'!F:F) -> 19.501 | J12: =SUMIF('Finished Recipe'!B:B, B12, 'Finished Recipe'!M:M) -> 13.50138 | K12: =G12-J12 -> 6.3262067 | L12: =J12/G12 -> 0.68093914 | M12: =K12/G12 -> 0.31906086
A13: FP40100009 | B13: TA-ORD-012 | C13: قسم التواصي | D13: التواصي سفري | E13: مقلوبة فول لحم 1 كيلو | F13: 0.16 | G13: 12.068966 | H13: =SUMIF('Sales 6.2026'!B:F,'All Menu'!B13,'Sales 6.2026'!F:F) -> 1 | J13: =SUMIF('Finished Recipe'!B:B, B13, 'Finished Recipe'!M:M) -> 6.6200007 | K13: =G13-J13 -> 5.4489649 | L13: =J13/G13 -> 0.54851434 | M13: =K13/G13 -> 0.45148566
A14: FP40100010 | B14: TA-ORD-014 | C14: قسم التواصي | D14: التواصي سفري | E14: كبسة دجاج 1 دجاجة | F14: 0.16 | G14: 8.6206897 | H14: =SUMIF('Sales 6.2026'!B:F,'All Menu'!B14,'Sales 6.2026'!F:F) -> 196 | J14: =SUMIF('Finished Recipe'!B:B, B14, 'Finished Recipe'!M:M) -> 5.0302468 | K14: =G14-J14 -> 3.5904429 | L14: =J14/G14 -> 0.58350862 | M14: =K14/G14 -> 0.41649138
A15: FP40100011 | B15: TA-ORD-015 | C15: قسم التواصي | D15: التواصي سفري | E15: قدرة دجاج 1 دجاجة | F15: 0.16 | G15: 8.6206897 | H15: =SUMIF('Sales 6.2026'!B:F,'All Menu'!B15,'Sales 6.2026'!F:F) -> 4 | J15: =SUMIF('Finished Recipe'!B:B, B15, 'Finished Recipe'!M:M) -> 4.776991 | K15: =G15-J15 -> 3.8436986 | L15: =J15/G15 -> 0.55413096 | M15: =K15/G15 -> 0.44586904
A16: FP40100012 | B16: TA-ORD-016 | C16: قسم التواصي | D16: التواصي سفري | E16: أوزي دجاج 1 دجاجة | F16: 0.16 | G16: 8.6206897 | H16: =SUMIF('Sales 6.2026'!B:F,'All Menu'!B16,'Sales 6.2026'!F:F) -> 49 | J16: =SUMIF('Finished Recipe'!B:B, B16, 'Finished Recipe'!M:M) -> 5.2035959 | K16: =G16-J16 -> 3.4170938 | L16: =J16/G16 -> 0.60361712 | M16: =K16/G16 -> 0.39638288
... A26: FP40100022 | B26: TA-ORD-040 | C26: قسم التواصي | D26: التواصي سفري2 | E26: روستو كتف او فخد مشوي /كيلو | F26: 0.16 | G26: 18.965517 | H26: =SUMIF('Sales 6.2026'!B:F,'All Menu'!B26,'Sales 6.2026'!F:F) -> 39.5 | J26: =SUMIF('Finished Recipe'!B:B, B26, 'Finished Recipe'!M:M) -> 14.227831 | K26: =G26-J26 -> 4.7376865 | L26: =J26/G26 -> 0.75019471 | M26: =K26/G26 -> 0.24980529
A27: FP40100023 | B27: TA-ORD-042 | C27: قسم التواصي | D27: التواصي سفري2 | E27: خروف بلدي محشي | F27: 0.16 | G27: 15.517241 | H27: =SUMIF('Sales 6.2026'!B:F,'All Menu'!B27,'Sales 6.2026'!F:F) -> 0 | J27: =SUMIF('Finished Recipe'!B:B, B27, 'Finished Recipe'!M:M) -> 13.911674 | K27: =G27-J27 -> 1.6055675 | L27: =J27/G27 -> 0.89653009 | M27: =K27/G27 -> 0.10346991 | N27: تم الحذف
A28: FP40100024 | B28: TA-ORD-043 | C28: قسم التواصي | D28: التواصي سفري2 | E28: خروف روماني محشي | F28: 0.16 | G28: 13.793103 | H28: =SUMIF('Sales 6.2026'!B:F,'All Menu'!B28,'Sales 6.2026'!F:F) -> 0 | J28: =SUMIF('Finished Recipe'!B:B, B28, 'Finished Recipe'!M:M) -> 21.081552 | K28: =G28-J28 -> -7.2884488 | L28: =J28/G28 -> 1.5284125 | M28: =K28/G28 -> -0.52841254
A29: FP40100025 | B29: TA-ORD-045 | C29: قسم التواصي | D29: التواصي سفري | E29: دجاجة على الفحم+سدر رز | F29: 0.16 | G29: 10.344828 | H29: =SUMIF('Sales 6.2026'!B:F,'All Menu'!B29,'Sales 6.2026'!F:F) -> 172.5 | J29: =SUMIF('Finished Recipe'!B:B, B29, 'Finished Recipe'!M:M) -> 5.4543656 | K29: =G29-J29 -> 4.890462 | L29: =J29/G29 -> 0.52725534 | M29: =K29/G29 -> 0.47274466
A30: FP40100026 | B30: TA-ORD-046 | C30: قسم التواصي | D30: التواصي سفري | E30: سدر رز + نص دجاجة عالفحم | F30: 0.16 | G30: 5.1724138 | H30: =SUMIF('Sales 6.2026'!B:F,'All Menu'!B30,'Sales 6.2026'!F:F) -> 26 | J30: =SUMIF('Finished Recipe'!B:B, B30, 'Finished Recipe'!M:M) -> 3.1807436 | K30: =G30-J30 -> 1.9916702 | L30: =J30/G30 -> 0.61494377 | M30: =K30/G30 -> 0.38505623
A31: FP40100027 | B31: TA-ORD-048 | C31: قسم التواصي | D31: التواصي سفري2 | E31: ورق عنب / كيلو | F31: 0.16 | G31: 15.517241 | H31: =SUMIF('Sales 6.2026'!B:F,'All Menu'!B31,'Sales 6.2026'!F:F) -> 19.5 | J31: =SUMIF('Finished Recipe'!B:B, B31, 'Finished Recipe'!M:M) -> 3.7891944 | K31: =G31-J31 -> 11.728047 | L31: =J31/G31 -> 0.24419253 | M31: =K31/G31 -> 0.75580747
A32: FP40100028 | B32: TA-ORD-049 | C32: قسم التواصي | D32: التواصي سفري2 | E32: كوسا / كيلو | F32: 0.16 | G32: 12.068966 | H32: =SUMIF('Sales 6.2026'!B:F,'All Menu'!B32,'Sales 6.2026'!F:F) -> 9 | J32: =SUMIF('Finished Recipe'!B:B, B32, 'Finished Recipe'!M:M) -> 3.0870831 | K32: =G32-J32 -> 8.9818824 | L32: =J32/G32 -> 0.25578688 | M32: =K32/G32 -> 0.74421312
A33: FP40100029 | B33: TA-ORD-050 | C33: قسم التواصي | D33: التواصي سفري2 | E33: كوسا 1ك +دوالي 1 ك+ ريش 1 ك | F33: 0.16 | G33: 38.793103 | H33: =SUMIF('Sales 6.2026'!B:F,'All Menu'!B33,'Sales 6.2026'!F:F) -> 10 | J33: =SUMIF('Finished Recipe'!B:B, B33, 'Finished Recipe'!M:M) -> 23.594877 | K33: =G33-J33 -> 15.198226 | L33: =J33/G33 -> 0.6082235 | M33: =K33/G33 -> 0.3917765
A34: FP40100030 | B34: TA-ORD-051 | C34: قسم التواصي | D34: التواصي سفري2 | E34: 1ك كوسا +1ك دوالي | F34: 0.16 | G34: 21.551724 | H34: =SUMIF('Sales 6.2026'!B:F,'All Menu'!B34,'Sales 6.2026'!F:F) -> 29 | J34: =SUMIF('Finished Recipe'!B:B, B34, 'Finished Recipe'!M:M) -> 9.8006828 | K34: =G34-J34 -> 11.751041 | L34: =J34/G34 -> 0.45475168 | M34: =K34/G34 -> 0.54524832
A35: FP40100031 | B35: TA-ORD-053 | C35: قسم التواصي | D35: التواصي سفري2 | E35: راس مطبوخ | F35: 0.16 | G35: 8.6206897 | H35: =SUMIF('Sales 6.2026'!B:F,'All Menu'!B35,'Sales 6.2026'!F:F) -> 1 | J35: =SUMIF('Finished Recipe'!B:B, B35, 'Finished Recipe'!M:M) -> 4.2948409 | K35: =G35-J35 -> 4.3258488 | L35: =J35/G35 -> 0.49820154 | M35: =K35/G35 -> 0.50179846
A36: FP40100032 | B36: TA-ORD-055 | C36: قسم التواصي | D36: التواصي سفري2 | E36: مقلوبة دجاجتين | F36: 0.16 | G36: 21.551724 | H36: =SUMIF('Sales 6.2026'!B:F,'All Menu'!B36,'Sales 6.2026'!F:F) -> 0 | J36: =SUMIF('Finished Recipe'!B:B, B36, 'Finished Recipe'!M:M) -> 10.726016 | K36: =G36-J36 -> 10.825708 | L36: =J36/G36 -> 0.49768716 | M36: =K36/G36 -> 0.50231284
A37: FP40100033 | B37: TA-ORD-056 | C37: قسم التواصي | D37: التواصي سفري2 | E37: اضافة نصف دجاجة | F37: 0.16 | G37: 6.0344828 | H37: =SUMIF('Sales 6.2026'!B:F,'All Menu'!B37,'Sales 6.2026'!F:F) -> 0 | J37: =SUMIF('Finished Recipe'!B:B, B37, 'Finished Recipe'!M:M) -> 1.7699991 | K37: =G37-J37 -> 4.2644836 | L37: =J37/G37 -> 0.29331414 | M37: =K37/G37 -> 0.70668586
A38: FP40100034 | B38: TA-ORD-059 | C38: قسم التواصي | D38: التواصي سفري2 | E38: منسف روماني كيلو | F38: 0.16 | G38: 17.241379 | H38: =SUMIF('Sales 6.2026'!B:F,'All Menu'!B38,'Sales 6.2026'!F:F) -> 13 | J38: =SUMIF('Finished Recipe'!B:B, B38, 'Finished Recipe'!M:M) -> 9.9595579 | K38: =G38-J38 -> 7.2818214 | L38: =J38/G38 -> 0.57765436 | M38: =K38/G38 -> 0.42234564
A39: FP40100035 | B39: TA-ORD-061 | C39: قسم التواصي | D39: التواصي سفري2 | E39: سدر VIP | F39: 0.16 | G39: 15.517241 | H39: =SUMIF('Sales 6.2026'!B:F,'All Menu'!B39,'Sales 6.2026'!F:F) -> 4 | J39: =SUMIF('Finished Recipe'!B:B, B39, 'Finished Recipe'!M:M) -> 9.7854384 | K39: =G39-J39 -> 5.731803 | L39: =J39/G39 -> 0.63061714 | M39: =K39/G39 -> 0.36938286
... A48: FP40200007 | B48: DI-APC-012 | C48: قسم الصالة | D48: مقبلات باردة صالة | E48: مثومة | F48: 0.16 | G48: 0.64655172 | H48: =SUMIF('Sales 6.2026'!B:F,'All Menu'!B48,'Sales 6.2026'!F:F) -> 1 | J48: =SUMIF('Finished Recipe'!B:B, B48, 'Finished Recipe'!M:M) -> 0.099846138 | K48: =G48-J48 -> 0.54670559 | L48: =J48/G48 -> 0.15442869 | M48: =K48/G48 -> 0.84557131
A49: FP40200008 | B49: DI-APC-014 | C49: قسم الصالة | D49: مقبلات باردة صالة | E49: سيرفس منسف | F49: 0.16 | G49: 0 | H49: =SUMIF('Sales 6.2026'!B:F,'All Menu'!B49,'Sales 6.2026'!F:F) -> 105 | J49: =SUMIF('Finished Recipe'!B:B, B49, 'Finished Recipe'!M:M) -> 0.212 | K49: =G49-J49 -> -0.212 | L49: 0 | M49: 0 | N49: ضيافة
A50: FP40200009 | B50: DI-APC-015 | C50: قسم الصالة | D50: مقبلات باردة صالة | E50: حمص بيروتي | F50: 0.16 | G50: 2.5431034 | H50: =SUMIF('Sales 6.2026'!B:F,'All Menu'!B50,'Sales 6.2026'!F:F) -> 3 | J50: =SUMIF('Finished Recipe'!B:B, B50, 'Finished Recipe'!M:M) -> 0.30320241 | K50: =G50-J50 -> 2.239901 | L50: =J50/G50 -> 0.11922535 | M50: =K50/G50 -> 0.88077465
A51: FP40200010 | B51: DI-APC-017 | C51: قسم الصالة | D51: مقبلات باردة صالة | E51: حمص المركزية | F51: 0.16 | G51: 2.8017241 | H51: =SUMIF('Sales 6.2026'!B:F,'All Menu'!B51,'Sales 6.2026'!F:F) -> 6 | J51: =SUMIF('Finished Recipe'!B:B, B51, 'Finished Recipe'!M:M) -> 0.31238329 | K51: =G51-J51 -> 2.4893408 | L51: =J51/G51 -> 0.11149681 | M51: =K51/G51 -> 0.88850319
A52: FP40200011 | B52: DI-APH-001 | C52: قسم الصالة | D52: مقبلات ساخنة صالة | E52: كبة مشوية | F52: 0.16 | G52: 1.2931034 | H52: =SUMIF('Sales 6.2026'!B:F,'All Menu'!B52,'Sales 6.2026'!F:F) -> 108 | J52: =SUMIF('Finished Recipe'!B:B, B52, 'Finished Recipe'!M:M) -> 0.50639403 | K52: =G52-J52 -> 0.78670942 | L52: =J52/G52 -> 0.39161138 | M52: =K52/G52 -> 0.60838862
A53: FP40200012 | B53: DI-APH-002 | C53: قسم الصالة | D53: مقبلات ساخنة صالة | E53: كبة مقلية | F53: 0.16 | G53: 1.5517241 | H53: =SUMIF('Sales 6.2026'!B:F,'All Menu'!B53,'Sales 6.2026'!F:F) -> 145 | J53: =SUMIF('Finished Recipe'!B:B, B53, 'Finished Recipe'!M:M) -> 1.2857409 | K53: =G53-J53 -> 0.26598319 | L53: =J53/G53 -> 0.82858861 | M53: =K53/G53 -> 0.17141139 | N53: حبتين
A54: FP40200013 | B54: DI-APH-003 | C54: قسم الصالة | D54: مقبلات ساخنة صالة | E54: مسخن رول | F54: 0.16 | G54: 1.5517241 | H54: =SUMIF('Sales 6.2026'!B:F,'All Menu'!B54,'Sales 6.2026'!F:F) -> 20 | J54: =SUMIF('Finished Recipe'!B:B, B54, 'Finished Recipe'!M:M) -> 0.23830171 | K54: =G54-J54 -> 1.3134224 | L54: =J54/G54 -> 0.15357222 | M54: =K54/G54 -> 0.84642778
A55: FP40200014 | B55: DI-APH-004 | C55: قسم الصالة | D55: مقبلات ساخنة صالة | E55: برك جبنة | F55: 0.16 | G55: 1.637931 | H55: =SUMIF('Sales 6.2026'!B:F,'All Menu'!B55,'Sales 6.2026'!F:F) -> 116 | J55: =SUMIF('Finished Recipe'!B:B, B55, 'Finished Recipe'!M:M) -> 0.17243675 | K55: =G55-J55 -> 1.4654943 | L55: =J55/G55 -> 0.10527717 | M55: =K55/G55 -> 0.89472283
A56: FP40200015 | B56: DI-APH-005 | C56: قسم الصالة | D56: مقبلات ساخنة صالة | E56: عش البلبل | F56: 0.16 | G56: 1.637931 | H56: =SUMIF('Sales 6.2026'!B:F,'All Menu'!B56,'Sales 6.2026'!F:F) -> 27 | J56: =SUMIF('Finished Recipe'!B:B, B56, 'Finished Recipe'!M:M) -> 0.35051063 | K56: =G56-J56 -> 1.2874204 | L56: =J56/G56 -> 0.21399596 | M56: =K56/G56 -> 0.78600404
A57: FP40200016 | B57: DI-APH-009 | C57: قسم الصالة | D57: مقبلات ساخنة صالة | E57: بطاطا مقلية | F57: 0.16 | G57: 1.6810345 | H57: =SUMIF('Sales 6.2026'!B:F,'All Menu'!B57,'Sales 6.2026'!F:F) -> 99 | J57: =SUMIF('Finished Recipe'!B:B, B57, 'Finished Recipe'!M:M) -> 0.136893 | K57: =G57-J57 -> 1.5441415 | L57: =J57/G57 -> 0.081433785 | M57: =K57/G57 -> 0.91856622
...

Sheet عرض
A1: كود الصنف | B1: اسم الصنف | C1: الكلفة | D1: سعر بيع شامل شريبة و عمولة | E1: سعر غير شامل عموله | F1: سعر غير شامل الضريبة | G1: هامش الربح | H1: نسبة هامش الربح
A2: TA-BBQ-061 | B2: بوكس كباب عادي | C2: =1.51737151318142*2 -> 3.034743 | D2: 6.514 | E2: =D2/1.3 -> 5.0107692 | F2: =E2/1.16 -> 4.3196286 | G2: =F2-C2 -> 1.2848856 | H2: =G2/F2 -> 0.2974528
A3: TA-BBQ-062 | B3: بوكس كباب سوبر | C3: =2.18107064418945*2 -> 4.3621413 | D3: 8.686 | E3: =D3/1.3 -> 6.6815385 | F3: =E3/1.16 -> 5.7599469 | G3: =F3-C3 -> 1.3978057 | H3: =G3/F3 -> 0.24267683

Sheet تفصيل الخروف 
B1: 12.177187 | C1: 12.77074 | D1: 11.935009 | E1: 13.948305 | F1: =E1+D1+C1+B1 -> 50.831241 | G1: السعر | H1: الاجمالي | I1: الخروف | J1: عدد الخرفان | L1: السعر كيلو ( الفاتورة ) | M1: اجمالي السعر
F2: =F1/4 -> 12.70781 | J2: 10 | L2: 10.25 | M2: =L2*M17 -> 2439.5
I3: اسم الصنف | M3: الكمية
A4: 5433 | B4: 4608 | C4: 4605 | D4: 5393 | E4: كتف | F4: =G4/1000 -> 0.012633003 | G4: 12.633003 | H4: =G4*M4 -> 735.2408 | I4: كتف | M4: 58.2 | N4: =M2-H5-H6-H7-H8-H9-H10-H11-H12-H13-H15-H16 -> 816 | O4: =N4/M4 -> 14.020619
C5: SF959 | D5: 979 | E5: شقف | F5: =G5/1000 -> 0.02 | G5: 20 | H5: =G5*M5 -> 382 | I5: شقف | M5: 19.1
D6: 4598 | E6: لية | F6: =G6/1000 -> 0.005 | G6: 5 | H6: =G6*M6 -> 168 | I6: لية | M6: 33.6
C7: 4614 | D7: 5392 | E7: ريش | F7: =G7/1000 -> 0.014 | G7: 14 | H7: =G7*M7 -> 340.2 | I7: ريش | M7: 24.3
B8: 4606 | C8: 4943 | D8: SF2025001 | E8: رفالات | F8: =G8/1000 -> 0.012 | G8: 12 | H8: =G8*M8 -> 177.6 | I8: رفالات + قص مجروم + زوايد | M8: 14.8
E9: بدنيات | F9: =G9/1000 -> 0.003 | G9: 3 | H9: =G9*M9 -> 52.5 | I9: بدنيات | M9: 17.5
C10: 5430 | D10: 4601 | E10: نتر | F10: =G10/1000 -> 0.003 | G10: 3 | H10: =G10*M10 -> 20.4 | I10: نتر | M10: 6.8
D11: 4762 | E11: كلاوي | F11: =G11/1000 -> 0.005 | G11: 5 | H11: =G11*M11 -> 6.45 | I11: كلاوي | M11: 1.29
D12: 4764 | E12: خصاوي | F12: =G12/1000 -> 0.005 | G12: 5 | H12: =G12*M12 -> 12.25 | I12: خصاوي | M12: 2.45
D13: 5436 | E13: فتايل | F13: =G13/1000 -> 0.021 | G13: 21 | H13: =G13*M13 -> 69.3 | I13: فتايل | M13: 3.3
E14: عروق + عرقيب + عظم | F14: =G14/1000 -> 0 | G14: 0 | H14: =G14*M14 -> 0 | I14: عروق + عرقيب + عظم | M14: 19.2
D15: SF2025001 | E15: زوايد ( احمر ) | F15: =G15/1000 -> 0.013 | G15: 13 | H15: =G15*M15 -> 191.1 | I15: زوايد ( احمر ) | M15: 14.7
D16: طلبات مارت | E16: اضلاع خروف 500 غرام | F16: =G16/1000 -> 0.0105 | G16: 10.5 | H16: =G16*M16 -> 203.7 | I16: اضلاع خروف 500غرام | M16: 19.4
G17: الاجمالي | I17: الوزن عند استلام ( الفاتورة ) | M17: 238
I20: الوزن قبل التقطيع | M20: 234.9
I23: الفاقد | M23: =M17-M20 -> 3.1
G24: =SUM(H4:H16) -> 2358.7408 | I24: صافي الوزن بعد التقطيع | M24: =SUM(M4:M16) -> 234.64

Sheet مسحوبات المواد الخام
A1: RM Item New Code | B1: Complete Item Description | D1: Cost / Storage Unit (JOD) | E1: Recipe Unit | F1: تصنيف | G1: Item Quantity | H1: Price Per Unit
A2: 4550 | B2: *****لبن زبادي 150 غم | C2: =SUMIF('Finished Recipe'!H:R,'مسحوبات المواد الخام'!A2,'Finished Recipe'!R:R) -> 0 | D2: 0.16 | E2: قطعة | F2: اجبان والبان | G2: 1 | H2: =D2/G2 -> 0.16
A3: 4552 | B3: لبن رايب 5 كغ***** | C3: =SUMIF('Finished Recipe'!H:R,'مسحوبات المواد الخام'!A3,'Finished Recipe'!R:R) -> 0 | D3: 4 | E3: غم | F3: اجبان والبان | G3: 5000 | H3: =D3/G3 -> 0.0008
A4: 4553 | B4: لبن مخيض 18 كغ***** | C4: =SUMIF('Finished Recipe'!H:R,'مسحوبات المواد الخام'!A4,'Finished Recipe'!R:R) -> 0 | D4: 0.42 | E4: مل | F4: اجبان والبان | G4: 1000 | H4: =D4/G4 -> 0.00042
A5: 4559 | B5: جبنة عكاوي 5 كغ***** | C5: =SUMIF('Finished Recipe'!H:R,'مسحوبات المواد الخام'!A5,'Finished Recipe'!R:R) -> 0 | D5: 4 | E5: غم | F5: اجبان والبان | G5: 1000 | H5: =D5/G5 -> 0.004
A6: 4560 | B6: جبنة بارميزان قالب***** | C6: =SUMIF('Finished Recipe'!H:R,'مسحوبات المواد الخام'!A6,'Finished Recipe'!R:R) -> 0 | D6: 11.363636 | E6: غم | F6: اجبان والبان | G6: 1000 | H6: =D6/G6 -> 0.011363636
A7: 4561 | B7: جبنة صفراء 950 غم***** | C7: =SUMIF('Finished Recipe'!H:R,'مسحوبات المواد الخام'!A7,'Finished Recipe'!R:R) -> 0 | D7: 4 | E7: غم | F7: اجبان والبان | G7: 1500 | H7: =D7/G7 -> 0.0026666667
A8: 4562 | B8: *****جبنة شدر احمر شرائح 2.270 كغ | C8: =SUMIF('Finished Recipe'!H:R,'مسحوبات المواد الخام'!A8,'Finished Recipe'!R:R) -> 0 | D8: 19.545 | E8: قطعة | F8: اجبان والبان | G8: 288 | H8: =D8/G8 -> 0.067864583
A9: 4564 | B9: جبنة حلوم 250 غم***** | C9: =SUMIF('Finished Recipe'!H:R,'مسحوبات المواد الخام'!A9,'Finished Recipe'!R:R) -> 0 | D9: 26.666667 | E9: غم | F9: اجبان والبان | G9: 3000 | H9: =D9/G9 -> 0.0088888889
A10: 4565 | B10: جبنة فيتا 16 كغ***** | C10: =SUMIF('Finished Recipe'!H:R,'مسحوبات المواد الخام'!A10,'Finished Recipe'!R:R) -> 0 | D10: 50.909 | E10: غم | F10: اجبان والبان | G10: 16000 | H10: =D10/G10 -> 0.0031818125
A11: 4566 | B11: زبدة صفائح 5*2 كغ***** | C11: =SUMIF('Finished Recipe'!H:R,'مسحوبات المواد الخام'!A11,'Finished Recipe'!R:R) -> 0 | D11: 18.269231 | E11: غم | F11: اجبان والبان | G11: 2500 | H11: =D11/G11 -> 0.0073076923
A12: 4623 | B12: زبدة مبسترة غير مملحة 1 كغ***** | C12: =SUMIF('Finished Recipe'!H:R,'مسحوبات المواد الخام'!A12,'Finished Recipe'!R:R) -> 0 | D12: 20.192 | E12: غم | F12: اجبان والبان | G12: 8000 | H12: =D12/G12 -> 0.002524
A13: 4624 | B13: جبنة موزريلا قالب 2.380 كغ***** | C13: =SUMIF('Finished Recipe'!H:R,'مسحوبات المواد الخام'!A13,'Finished Recipe'!R:R) -> 0 | D13: 10 | E13: غم | F13: اجبان والبان | G13: 19040 | H13: =D13/G13 -> 0.00052521008
... A377: 5445 | B377: عجين كلاج عمر | C377: =SUMIF('Finished Recipe'!H:R,'مسحوبات المواد الخام'!A377,'Finished Recipe'!R:R) -> 0 | D377: 2.7 | E377: غم | F377: مواد تموينية | G377: 800 | H377: =D377/G377 -> 0.003375
A378: 5254 | B378: نجمة اليانسون***** | C378: =SUMIF('Finished Recipe'!H:R,'مسحوبات المواد الخام'!A378,'Finished Recipe'!R:R) -> 0 | D378: 10.345 | E378: غم | G378: 1000 | H378: =D378/G378 -> 0.010345
A379: 5255 | B379: زيت دوار الشمس 20لتر (شورتنج)***** | C379: =SUMIF('Finished Recipe'!H:R,'مسحوبات المواد الخام'!A379,'Finished Recipe'!R:R) -> 0 | D379: 25 | E379: مل | G379: 18000 | H379: =D379/G379 -> 0.0013888889
A380: 5257 | B380: بهار شيتوس***** | C380: =SUMIF('Finished Recipe'!H:R,'مسحوبات المواد الخام'!A380,'Finished Recipe'!R:R) -> 0 | D380: 5.172 | E380: غم | G380: 1000 | H380: =D380/G380 -> 0.005172
A381: 5260 | B381: فيليه فيل هندي 18ك***** | C381: =SUMIF('Finished Recipe'!H:R,'مسحوبات المواد الخام'!A381,'Finished Recipe'!R:R) -> 0 | D381: 7 | E381: غم | G381: 1000 | H381: =D381/G381 -> 0.007
A382: 5264 | B382: سدر المنيوم***** | C382: =SUMIF('Finished Recipe'!H:R,'مسحوبات المواد الخام'!A382,'Finished Recipe'!R:R) -> 0 | D382: 4.55 | E382: قطعة | G382: 1 | H382: =D382/G382 -> 4.55
A383: 5269 | B383: سدر بلاستيك 40سم***** | C383: =SUMIF('Finished Recipe'!H:R,'مسحوبات المواد الخام'!A383,'Finished Recipe'!R:R) -> 0 | D383: 0.45 | E383: قطعة | G383: 1 | H383: =D383/G383 -> 0.45
A384: 5270 | B384: سدر بلاستيك 45سم***** | C384: =SUMIF('Finished Recipe'!H:R,'مسحوبات المواد الخام'!A384,'Finished Recipe'!R:R) -> 0 | D384: 0.5 | E384: قطعة | G384: 1 | H384: =D384/G384 -> 0.5
A385: 5276 | B385: رول ورقي***** | C385: =SUMIF('Finished Recipe'!H:R,'مسحوبات المواد الخام'!A385,'Finished Recipe'!R:R) -> 0 | D385: 2.75 | E385: غم | G385: 1000 | H385: =D385/G385 -> 0.00275
A386: 5277 | B386: اكياس مطبوع وسط 45سم***** | C386: =SUMIF('Finished Recipe'!H:R,'مسحوبات المواد الخام'!A386,'Finished Recipe'!R:R) -> 0 | D386: 1.65 | E386: غم | G386: 1000 | H386: =D386/G386 -> 0.00165
A387: 5278 | B387: ملاعق vip(1000 حبة)***** | C387: =SUMIF('Finished Recipe'!H:R,'مسحوبات المواد الخام'!A387,'Finished Recipe'!R:R) -> 0 | D387: 0.023 | E387: قطعة | G387: 1 | H387: =D387/G387 -> 0.023
A388: 5279 | B388: اكياس مطبوع عريض 55سم***** | C388: =SUMIF('Finished Recipe'!H:R,'مسحوبات المواد الخام'!A388,'Finished Recipe'!R:R) -> 0 | D388: 1.65 | E388: غم | G388: 1000 | H388: =D388/G388 -> 0.00165
A389: 5280 | B389: ورق مع قصدير مطبوع***** | C389: =SUMIF('Finished Recipe'!H:R,'مسحوبات المواد الخام'!A389,'Finished Recipe'!R:R) -> 0 | D389: 0.025 | E389: قطعة | G389: 1 | H389: =D389/G389 -> 0.025
... A406: 5316 | B406: خروف بلدي وزن كبير***** | C406: =SUMIF('Finished Recipe'!H:R,'مسحوبات المواد الخام'!A406,'Finished Recipe'!R:R) -> 0 | D406: 0 | E406: غم | G406: 1000 | H406: =D406/G406 -> 0
A407: 5320 | B407: سلفر سايد برازيلي***** | C407: =SUMIF('Finished Recipe'!H:R,'مسحوبات المواد الخام'!A407,'Finished Recipe'!R:R) -> 0 | E407: غم | G407: 1000 | H407: =D407/G407 -> 0
A408: 5321 | B408: توب سايد برازيلي***** | C408: =SUMIF('Finished Recipe'!H:R,'مسحوبات المواد الخام'!A408,'Finished Recipe'!R:R) -> 0 | D408: 6.25 | E408: غم | G408: 1000 | H408: =D408/G408 -> 0.00625
A409: 5327 | B409: دجاج تندر***** | C409: =SUMIF('Finished Recipe'!H:R,'مسحوبات المواد الخام'!A409,'Finished Recipe'!R:R) -> 0 | D409: 4 | E409: غم | G409: 1000 | H409: =D409/G409 -> 0.004
A410: 5329 | B410: اكياس مطبوع سوبر 60سم***** | C410: =SUMIF('Finished Recipe'!H:R,'مسحوبات المواد الخام'!A410,'Finished Recipe'!R:R) -> 0 | D410: 1.65 | E410: قطعة | G410: 1 | H410: =D410/G410 -> 1.65
A411: 5330 | B411: صحون قصدير مدور rc 18***** | C411: =SUMIF('Finished Recipe'!H:R,'مسحوبات المواد الخام'!A411,'Finished Recipe'!R:R) -> 0 | D411: 0.078 | E411: قطعة | G411: 1 | H411: =D411/G411 -> 0.078
A412: 5332 | B412: فخذ عجل افريقي***** | C412: =SUMIF('Finished Recipe'!H:R,'مسحوبات المواد الخام'!A412,'Finished Recipe'!R:R) -> 0 | E412: غم | G412: 1000 | H412: =D412/G412 -> 0
A413: 5333 | B413: فخذ خروف روماني***** | C413: =SUMIF('Finished Recipe'!H:R,'مسحوبات المواد الخام'!A413,'Finished Recipe'!R:R) -> 0 | E413: غم | G413: 1000 | H413: =D413/G413 -> 0
A414: 5334 | B414: فخذ خروف بلدي***** | C414: =SUMIF('Finished Recipe'!H:R,'مسحوبات المواد الخام'!A414,'Finished Recipe'!R:R) -> 0 | E414: غم | G414: 1000 | H414: =D414/G414 -> 0
A415: 5335 | B415: خروف روماني مفصل***** | C415: =SUMIF('Finished Recipe'!H:R,'مسحوبات المواد الخام'!A415,'Finished Recipe'!R:R) -> 0 | E415: غم | G415: 1000 | H415: =D415/G415 -> 0
A416: 5336 | B416: خروف بلدي مفصل***** | C416: =SUMIF('Finished Recipe'!H:R,'مسحوبات المواد الخام'!A416,'Finished Recipe'!R:R) -> 0 | E416: غم | G416: 1000 | H416: =D416/G416 -> 0
A417: 5337 | B417: نكل عجل برازيلي***** | C417: =SUMIF('Finished Recipe'!H:R,'مسحوبات المواد الخام'!A417,'Finished Recipe'!R:R) -> 0 | E417: غم | G417: 1000 | H417: =D417/G417 -> 0
A418: 5339 | B418: فخارات كبيرة***** | C418: =SUMIF('Finished Recipe'!H:R,'مسحوبات المواد الخام'!A418,'Finished Recipe'!R:R) -> 0 | D418: 1.5 | E418: قطعة | G418: 1 | H418: =D418/G418 -> 1.5
A419: 5341 | B419: كرشات عجل***** | C419: =SUMIF('Finished Recipe'!H:R,'مسحوبات المواد الخام'!A419,'Finished Recipe'!R:R) -> 0 | D419: 1.5 | E419: قطعة | G419: 1 | H419: =D419/G419 -> 1.5
...

Sheet قطعيات العجل
A1: انواع العجل | O1: الرقم المرجعي | P1: الاصنف | Q1: سعر كيلو | R1: سعر غرام
A2: قطعيات العجل مشكل ( برازيلي - افريقي - بلدي ) | L2: 5321 | M2: توب سايد برازيلي***** | N2: 1 | O2: 5373 | P2: قطعيات عجل مشكلة | Q2: 7.47 | R2: =Q2/1000 -> 0.00747 | S2: 8.5 | T2: 7.6
A3: # | B3: الاسم عربي | C3: الاسم انجليزي | D3: النوع | E3: توحيد الاسماء | F3: الكود سسم | G3: الاسم سستم | L3: 5337 | M3: توب برازيلي***** | N3: 1 | O3: 5401 | P3: روز بيف | Q3: 10.5 | R3: =Q3/1000 -> 0.0105
A4: 1 | B4: توب سايد | C4: Topside | D4: ( برازيلي - افريقي - بلدي ) | E4: قطعيات العجل مشكل ( برازيلي - افريقي - بلدي ) | F4: 5373 | G4: قطعيات عجل مشكلة | H4: 5321 | I4: توب سايد برازيلي***** | J4: 5337 | K4: توب برازيلي***** | L4: 5360 | M4: بريسكت عجل برازيلي***** | N4: 1 | O4: 5398 | P4: فيليه | Q4: 14.5 | R4: =Q4/1000 -> 0.0145
A5: 2 | B5: نعل سايد | C5: Silverside | D5: ( برازيلي - افريقي - بلدي ) | E5: قطعيات العجل مشكل ( برازيلي - افريقي - بلدي ) | F5: 5373 | G5: قطعيات عجل مشكلة | L5: 5351 | M5: شولدر***** | N5: 1
A6: 3 | B6: سليف سايد | C6: Thick Flank | D6: ( برازيلي - افريقي - بلدي ) | E6: قطعيات العجل مشكل ( برازيلي - افريقي - بلدي ) | F6: 5373 | G6: قطعيات عجل مشكلة | L6: 5395 | M6: فخد عجل بلدي | N6: 1
A7: 4 | B7: برسكة | C7: Brisket | D7: ( برازيلي - افريقي - بلدي ) | E7: قطعيات العجل مشكل ( برازيلي - افريقي - بلدي ) | F7: 5373 | G7: قطعيات عجل مشكلة | H7: 5360 | I7: بريسكت عجل برازيلي***** | L7: 5375 | M7: لحمة عجل برازيلي | N7: 1
A8: 5 | B8: شولدر | C8: Shoulder | D8: ( برازيلي - افريقي - بلدي ) | E8: قطعيات العجل مشكل ( برازيلي - افريقي - بلدي ) | F8: 5373 | G8: قطعيات عجل مشكلة | H8: 5351 | I8: شولدر***** | L8: 5400 | M8: لحم عجل مفروم بلدي | N8: 1
A9: 6 | B9: فخذ عجل | C9: Beef Leg | D9: ( برازيلي - افريقي - بلدي ) | E9: قطعيات العجل مشكل ( برازيلي - افريقي - بلدي ) | F9: 5373 | G9: قطعيات عجل مشكلة | H9: 5395 | I9: فخد عجل بلدي | J9: 5332 | K9: فخذ عجل مستورد***** | L9: 5347 | M9: رب اي عجل مستورد | N9: 2 | P9: 1 | Q9: 9.25 | R9: 8.25 | S9: 9.25 | T9: 9.75 | U9: 9.25 | V9: 8.8 | W9: 8.8 | X9: 9.25 | Y9: 8.25 | Z9: 9.25 | AA9: =SUM(Q9:Z9) -> 90.1 | AB9: =AA9/10 -> 9.01
A10: 7 | B10: لحمة عجل برازيلي | D10: ( برازيلي - افريقي - بلدي ) | E10: قطعيات العجل مشكل ( برازيلي - افريقي - بلدي ) | F10: 5373 | G10: قطعيات عجل مشكلة | H10: 5375 | I10: لحمة عجل برازيلي | L10: 4585 | M10: لحم بقري ستربلوين مبرد (لحم بقري روزبيف) افريقي***** | N10: 2 | P10: 2 | Q10: 12.9
A11: 8 | B11: لحم عجل مفروم بلدي | D11: ( برازيلي - افريقي - بلدي ) | E11: قطعيات العجل مشكل ( برازيلي - افريقي - بلدي ) | F11: 5373 | G11: قطعيات عجل مشكلة | H11: 5400 | I11: لحم عجل مفروم بلدي | L11: 4587 | M11: لحم بقري تندرلوين بدون عظم مبرد (لحم بقري فيليه) برازيلي***** | N11: 3 | P11: 3
A12: روز بيف ( برازيلي - افريقي - بلدي ) | L12: 4586 | M12: لحم بقري تندرلوين بدون عظم مبرد (لحم بقري فيليه) افريقي***** | N12: 3
A13: # | B13: الاسم عربي | C13: الاسم انجليزي | D13: النوع | E13: توحيد الاسماء | F13: الكود سسم | G13: الاسم سستم | L13: 5398 | M13: فيليه بلدي 14 | N13: 3
A14: 1 | B14: ريب آي | C14: Ribeye | D14: ( برازيلي - افريقي - بلدي ) | E14: روز بيف ( برازيلي - افريقي - بلدي ) | F14: 5401 | G14: روز بيف | H14: 5347 | I14: رب اي عجل مستورد | L14: 5441 | M14: فيليه روماني | N14: 3
A15: 2 | B15: كيوب رول | C15: Cube Roll | D15: ( برازيلي - افريقي - بلدي ) | E15: روز بيف ( برازيلي - افريقي - بلدي ) | F15: 5401 | G15: روز بيف | L15: 5349 | M15: فيليه افريقي***** | N15: 3
A16: 3 | B16: ستريب لوين | C16: Striploin | D16: ( برازيلي - افريقي - بلدي ) | E16: روز بيف ( برازيلي - افريقي - بلدي ) | F16: 5401 | G16: روز بيف | H16: 4585 | I16: لحم بقري ستربلوين مبرد (لحم بقري روزبيف) افريقي***** | L16: 5348 | M16: فيليه برازيلي***** | N16: 3
A17: فيليه ( برازيلي - افريقي - بلدي ) | L17: 5332 | M17: فخذ عجل مستورد***** | N17: 1
A18: # | B18: الاسم عربي | C18: الاسم انجليزي | D18: النوع | E18: توحيد الاسماء | F18: الكود سسم | G18: الاسم سستم | L18: 4594 | M18: فخذ عجل بلدي طازج***** | N18: 1
A19: 1 | B19: تندرلوين | C19: Tenderloin | D19: ( برازيلي - افريقي - بلدي ) | E19: فيليه ( برازيلي - افريقي - بلدي ) | F19: 5398 | G19: فيليه | H19: 4586 | I19: لحم بقري تندرلوين بدون عظم مبرد (لحم بقري فيليه) افريقي***** | J19: 4587 | K19: لحم بقري تندرلوين بدون عظم مبرد (لحم بقري فيليه) برازيلي*****
A20: 2 | B20: فيليه منظف | C20: Cleaned Tenderloin | D20: ( برازيلي - افريقي - بلدي ) | E20: فيليه ( برازيلي - افريقي - بلدي ) | F20: 5398 | G20: فيليه | H20: 5398 | I20: فيليه بلدي 14
F21: 5398 | G21: فيليه | H21: 5441 | I21: فيليه روماني | J21: 5348 | K21: فيليه برازيلي*****
H22: 5349 | I22: فيليه افريقي*****

Sheet Semi Finished Recipe
A1: odoo | B1: SF Item Code | D1: SF Item Name | E1: odoo | F1: RM Item New Code | G1: Complete Item Description | H1: الكمية بالضربة | I1: Unit | J1: الكمية المعادلة | K1: Cost Per Unit | L1: Total Cost | M1: Menu / SF
A2: SF20200007 | B2: SF2011 | D2: =VLOOKUP(B2, 'RM & SF'!B:C, 2, 0) -> عجين الصفيحة والمناقيش | E2: اضافة اودو | F2: 4146 | G2: =VLOOKUP(F2, 'RM & SF'!B:C, 2, 0) -> طحين ابيض زهرة متعدد الاستخدامات***** | H2: 9000 | I2: =VLOOKUP(F2, 'RM & SF'!B:H, 4, 0) -> غم | J2: =H2/7.708 -> 1167.6181 | K2: =VLOOKUP(F2, 'RM & SF'!B:H, 7, 0) -> 0.00032 | L2: =K2*J2 -> 0.37363778 | M2: Semi Finished Item
A3: SF20200007 | B3: SF2011 | D3: =VLOOKUP(B3, 'RM & SF'!B:C, 2, 0) -> عجين الصفيحة والمناقيش | E3: WH11090001 | F3: 4153 | G3: =VLOOKUP(F3, 'RM & SF'!B:C, 2, 0) -> سكر ابيض ناعم***** | H3: 430 | I3: =VLOOKUP(F3, 'RM & SF'!B:H, 4, 0) -> غم | J3: =H3/7.708 -> 55.786196 | K3: =VLOOKUP(F3, 'RM & SF'!B:H, 7, 0) -> 0.000525 | L3: =K3*J3 -> 0.029287753 | M3: Semi Finished Item
A4: SF20200007 | B4: SF2011 | D4: =VLOOKUP(B4, 'RM & SF'!B:C, 2, 0) -> عجين الصفيحة والمناقيش | E4: اضافة اودو | F4: 4014 | G4: =VLOOKUP(F4, 'RM & SF'!B:C, 2, 0) -> حليب بودرة 1.800 كغ***** | H4: 52 | I4: =VLOOKUP(F4, 'RM & SF'!B:H, 4, 0) -> غم | J4: =H4/7.708 -> 6.7462377 | K4: =VLOOKUP(F4, 'RM & SF'!B:H, 7, 0) -> 0.0050266667 | L4: =K4*J4 -> 0.033911088 | M4: Semi Finished Item
A5: SF20200007 | B5: SF2011 | D5: =VLOOKUP(B5, 'RM & SF'!B:C, 2, 0) -> عجين الصفيحة والمناقيش | E5: اضافة اودو | F5: 4113 | G5: =VLOOKUP(F5, 'RM & SF'!B:C, 2, 0) -> خميرة فورية 500 غم***** | H5: 42 | I5: =VLOOKUP(F5, 'RM & SF'!B:H, 4, 0) -> غم | J5: =H5/7.708 -> 5.4488843 | K5: =VLOOKUP(F5, 'RM & SF'!B:H, 7, 0) -> 0.0024911111 | L5: =K5*J5 -> 0.013573776 | M5: Semi Finished Item
A6: SF20200007 | B6: SF2011 | D6: =VLOOKUP(B6, 'RM & SF'!B:C, 2, 0) -> عجين الصفيحة والمناقيش | E6: اضافة اودو | F6: 3 | G6: =VLOOKUP(F6, 'RM & SF'!B:C, 2, 0) -> مياه حنفية | H6: 6600 | I6: =VLOOKUP(F6, 'RM & SF'!B:H, 4, 0) -> مل | J6: =H6/7.708 -> 856.25324 | K6: =VLOOKUP(F6, 'RM & SF'!B:H, 7, 0) -> 0 | L6: =K6*J6 -> 0 | M6: Semi Finished Item
A7: SF20200007 | B7: SF2011 | D7: =VLOOKUP(B7, 'RM & SF'!B:C, 2, 0) -> عجين الصفيحة والمناقيش | E7: WH11080002 | F7: 4160 | G7: =VLOOKUP(F7, 'RM & SF'!B:C, 2, 0) -> زيت صويا 18 لتر***** | H7: 90 | I7: =VLOOKUP(F7, 'RM & SF'!B:H, 4, 0) -> مل | J7: =H7/7.708 -> 11.676181 | K7: =VLOOKUP(F7, 'RM & SF'!B:H, 7, 0) -> 0.001335 | L7: =K7*J7 -> 0.015587701 | M7: Semi Finished Item
A8: SF20200006 | B8: SF2012 | D8: =VLOOKUP(B8, 'RM & SF'!B:C, 2, 0) -> عجين برك وعش البلبل | E8: اضافة اودو | F8: 4146 | G8: =VLOOKUP(F8, 'RM & SF'!B:C, 2, 0) -> طحين ابيض زهرة متعدد الاستخدامات***** | H8: 12000 | I8: =VLOOKUP(F8, 'RM & SF'!B:H, 4, 0) -> غم | J8: =H8/19.8 -> 606.06061 | K8: =VLOOKUP(F8, 'RM & SF'!B:H, 7, 0) -> 0.00032 | L8: =K8*J8 -> 0.19393939 | M8: Semi Finished Item
A9: SF20200006 | B9: SF2012 | D9: =VLOOKUP(B9, 'RM & SF'!B:C, 2, 0) -> عجين برك وعش البلبل | E9: WH11090001 | F9: 4153 | G9: =VLOOKUP(F9, 'RM & SF'!B:C, 2, 0) -> سكر ابيض ناعم***** | H9: 1200 | I9: =VLOOKUP(F9, 'RM & SF'!B:H, 4, 0) -> غم | J9: =H9/19.8 -> 60.606061 | K9: =VLOOKUP(F9, 'RM & SF'!B:H, 7, 0) -> 0.000525 | L9: =K9*J9 -> 0.031818182 | M9: Semi Finished Item
A10: SF20200006 | B10: SF2012 | D10: =VLOOKUP(B10, 'RM & SF'!B:C, 2, 0) -> عجين برك وعش البلبل | E10: اضافة اودو | F10: 3 | G10: =VLOOKUP(F10, 'RM & SF'!B:C, 2, 0) -> مياه حنفية | H10: 6890 | I10: =VLOOKUP(F10, 'RM & SF'!B:H, 4, 0) -> مل | J10: =H10/19.8 -> 347.9798 | K10: =VLOOKUP(F10, 'RM & SF'!B:H, 7, 0) -> 0 | L10: =K10*J10 -> 0 | M10: Semi Finished Item
A11: SF20200006 | B11: SF2012 | D11: =VLOOKUP(B11, 'RM & SF'!B:C, 2, 0) -> عجين برك وعش البلبل | E11: WH11080002 | F11: 4160 | G11: =VLOOKUP(F11, 'RM & SF'!B:C, 2, 0) -> زيت صويا 18 لتر***** | H11: 250 | I11: =VLOOKUP(F11, 'RM & SF'!B:H, 4, 0) -> مل | J11: =H11/19.8 -> 12.626263 | K11: =VLOOKUP(F11, 'RM & SF'!B:H, 7, 0) -> 0.001335 | L11: =K11*J11 -> 0.016856061 | M11: Semi Finished Item
A12: SF20200006 | B12: SF2012 | D12: =VLOOKUP(B12, 'RM & SF'!B:C, 2, 0) -> عجين برك وعش البلبل | E12: WH11060003 | F12: 4152 | G12: =VLOOKUP(F12, 'RM & SF'!B:C, 2, 0) -> ملح طعام 750غم***** | H12: 50 | I12: =VLOOKUP(F12, 'RM & SF'!B:H, 4, 0) -> غم | J12: =H12/19.8 -> 2.5252525 | K12: =VLOOKUP(F12, 'RM & SF'!B:H, 7, 0) -> 0.00017066667 | L12: =K12*J12 -> 0.00043097643 | M12: Semi Finished Item
A13: SF20200006 | B13: SF2012 | D13: =VLOOKUP(B13, 'RM & SF'!B:C, 2, 0) -> عجين برك وعش البلبل | E13: WH11130004 | F13: 4566 | G13: =VLOOKUP(F13, 'RM & SF'!B:C, 2, 0) -> زبدة صفائح 5*2 كغ***** | H13: 3000 | I13: =VLOOKUP(F13, 'RM & SF'!B:H, 4, 0) -> غم | J13: =H13/19.8 -> 151.51515 | K13: =VLOOKUP(F13, 'RM & SF'!B:H, 7, 0) -> 0.002 | L13: =K13*J13 -> 0.3030303 | M13: Semi Finished Item
A14: SF20400005 | B14: SF962 | D14: =VLOOKUP(B14, 'RM & SF'!B:C, 2, 0) -> لحمة الصفيحة بلبن المشغل | E14: اضافة اودو | F14: 5373 | G14: =VLOOKUP(F14, 'RM & SF'!B:C, 2, 0) -> قطعيات عجل مشكلة | H14: 185.18519 | I14: =VLOOKUP(F14, 'RM & SF'!B:H, 4, 0) -> غم | J14: =(H14/1076)*1000 -> 172.10519 | K14: =VLOOKUP(F14, 'RM & SF'!B:H, 7, 0) -> 0.00901 | L14: =K14*J14 -> 1.5506678 | M14: Semi Finished Item
A15: SF20400005 | B15: SF962 | D15: =VLOOKUP(B15, 'RM & SF'!B:C, 2, 0) -> لحمة الصفيحة بلبن المشغل | E15: اضافة اودو | F15: SF2025001 | G15: =VLOOKUP(F15, 'RM & SF'!B:C, 2, 0) -> لحم قص مجروم | H15: 277.77778 | I15: =VLOOKUP(F15, 'RM & SF'!B:H, 4, 0) -> غم | J15: =(H15/1076)*1000 -> 258.15779 | K15: =VLOOKUP(F15, 'RM & SF'!B:H, 7, 0) -> 0.014053846 | L15: =K15*J15 -> 3.6281098 | M15: Semi Finished Item
A16: SF20400005 | B16: SF962 | D16: =VLOOKUP(B16, 'RM & SF'!B:C, 2, 0) -> لحمة الصفيحة بلبن المشغل | E16: WH11140013 | F16: 4503 | G16: =VLOOKUP(F16, 'RM & SF'!B:C, 2, 0) -> بصل ناشف دفش***** | H16: 185.18519 | I16: =VLOOKUP(F16, 'RM & SF'!B:H, 4, 0) -> غم | J16: =(H16/1076)*1000 -> 172.10519 | K16: =VLOOKUP(F16, 'RM & SF'!B:H, 7, 0) -> 0.00025 | L16: =K16*J16 -> 0.043026298 | M16: Semi Finished Item
A17: SF20400005 | B17: SF962 | D17: =VLOOKUP(B17, 'RM & SF'!B:C, 2, 0) -> لحمة الصفيحة بلبن المشغل | E17: WH11060019 | F17: 4211 | G17: =VLOOKUP(F17, 'RM & SF'!B:C, 2, 0) -> كزبرة ناعمة***** | H17: 9.2592593 | I17: =VLOOKUP(F17, 'RM & SF'!B:H, 4, 0) -> غم | J17: =(H17/1076)*1000 -> 8.6052595 | K17: =VLOOKUP(F17, 'RM & SF'!B:H, 7, 0) -> 0.001509 | L17: =K17*J17 -> 0.012985337 | M17: Semi Finished Item
A18: SF20400005 | B18: SF962 | D18: =VLOOKUP(B18, 'RM & SF'!B:C, 2, 0) -> لحمة الصفيحة بلبن المشغل | E18: WH11060003 | F18: 4152 | G18: =VLOOKUP(F18, 'RM & SF'!B:C, 2, 0) -> ملح طعام 750غم***** | H18: 11.574074 | I18: =VLOOKUP(F18, 'RM & SF'!B:H, 4, 0) -> غم | J18: =(H18/1076)*1000 -> 10.756574 | K18: =VLOOKUP(F18, 'RM & SF'!B:H, 7, 0) -> 0.00017066667 | L18: =K18*J18 -> 0.0018357887 | M18: Semi Finished Item
A19: SF20400005 | B19: SF962 | D19: =VLOOKUP(B19, 'RM & SF'!B:C, 2, 0) -> لحمة الصفيحة بلبن المشغل | E19: WH11060030 | F19: 4218 | G19: =VLOOKUP(F19, 'RM & SF'!B:C, 2, 0) -> بهارات مشكلة***** | H19: 23.148148 | I19: =VLOOKUP(F19, 'RM & SF'!B:H, 4, 0) -> غم | J19: =(H19/1076)*1000 -> 21.513149 | K19: =VLOOKUP(F19, 'RM & SF'!B:H, 7, 0) -> 0.003017 | L19: =K19*J19 -> 0.06490517 | M19: Semi Finished Item
A20: SF20400005 | B20: SF962 | D20: =VLOOKUP(B20, 'RM & SF'!B:C, 2, 0) -> لحمة الصفيحة بلبن المشغل | E20: WH11250008 | F20: 4006 | G20: =VLOOKUP(F20, 'RM & SF'!B:C, 2, 0) -> دبس رمان 5 كغ (مادة أولية)***** | H20: 46.296296 | I20: =VLOOKUP(F20, 'RM & SF'!B:H, 4, 0) -> غم | J20: =(H20/1076)*1000 -> 43.026298 | K20: =VLOOKUP(F20, 'RM & SF'!B:H, 7, 0) -> 0.001508 | L20: =K20*J20 -> 0.064883657 | M20: Semi Finished Item
A21: SF20400005 | B21: SF962 | D21: =VLOOKUP(B21, 'RM & SF'!B:C, 2, 0) -> لحمة الصفيحة بلبن المشغل | E21: WH11130010 | F21: 4552 | G21: =VLOOKUP(F21, 'RM & SF'!B:C, 2, 0) -> لبن رايب 5 كغ***** | H21: 300.92593 | I21: =VLOOKUP(F21, 'RM & SF'!B:H, 4, 0) -> غم | J21: =(H21/1076)*1000 -> 279.67093 | K21: =VLOOKUP(F21, 'RM & SF'!B:H, 7, 0) -> 0.0008 | L21: =K21*J21 -> 0.22373675 | M21: Semi Finished Item
A22: SF20400005 | B22: SF962 | D22: =VLOOKUP(B22, 'RM & SF'!B:C, 2, 0) -> لحمة الصفيحة بلبن المشغل | E22: اضافة اودو | F22: 4166 | G22: =VLOOKUP(F22, 'RM & SF'!B:C, 2, 0) -> طحينية 18 كغ***** | H22: 37.037037 | I22: =VLOOKUP(F22, 'RM & SF'!B:H, 4, 0) -> غم | J22: =(H22/1076)*1000 -> 34.421038 | K22: =VLOOKUP(F22, 'RM & SF'!B:H, 7, 0) -> 0.002010582 | L22: =K22*J22 -> 0.06920632 | M22: Semi Finished Item | N22: تحديث
A23: SF20400005 | B23: SF962 | D23: =VLOOKUP(B23, 'RM & SF'!B:C, 2, 0) -> لحمة الصفيحة بلبن المشغل | E23: اضافة اودو | F23: 5037 | G23: =VLOOKUP(F23, 'RM & SF'!B:C, 2, 0) -> عصفر ريش***** | H23: 0.46296296 | I23: =VLOOKUP(F23, 'RM & SF'!B:H, 4, 0) -> غم | J23: =(H23/1076)*1000 -> 0.43026298 | K23: =VLOOKUP(F23, 'RM & SF'!B:H, 7, 0) -> 0.017241 | L23: =K23*J23 -> 0.007418164 | M23: Semi Finished Item
A24: SF20600004 | B24: SF2013 | D24: =VLOOKUP(B24, 'RM & SF'!B:C, 2, 0) -> لحمة مجرمشة | E24: اضافة اودو | F24: SF2025001 | G24: =VLOOKUP(F24, 'RM & SF'!B:C, 2, 0) -> لحم قص مجروم | H24: 100 | I24: =VLOOKUP(F24, 'RM & SF'!B:H, 4, 0) -> غم | J24: =H24/1 -> 100 | K24: =VLOOKUP(F24, 'RM & SF'!B:H, 7, 0) -> 0.014053846 | L24: =K24*J24 -> 1.4053846 | M24: Semi Finished Item
A25: SF20600004 | B25: SF2013 | D25: =VLOOKUP(B25, 'RM & SF'!B:C, 2, 0) -> لحمة مجرمشة | E25: WH11140001 | F25: 4491 | G25: =VLOOKUP(F25, 'RM & SF'!B:C, 2, 0) -> بندورة جامدة***** | H25: 75 | I25: =VLOOKUP(F25, 'RM & SF'!B:H, 4, 0) -> غم | J25: =H25/1 -> 75 | K25: =VLOOKUP(F25, 'RM & SF'!B:H, 7, 0) -> 0.0005 | L25: =K25*J25 -> 0.0375 | M25: Semi Finished Item
A26: SF20600004 | B26: SF2013 | D26: =VLOOKUP(B26, 'RM & SF'!B:C, 2, 0) -> لحمة مجرمشة | E26: WH11140013 | F26: 4503 | G26: =VLOOKUP(F26, 'RM & SF'!B:C, 2, 0) -> بصل ناشف دفش***** | H26: 65 | I26: =VLOOKUP(F26, 'RM & SF'!B:H, 4, 0) -> غم | J26: =H26/1 -> 65 | K26: =VLOOKUP(F26, 'RM & SF'!B:H, 7, 0) -> 0.00025 | L26: =K26*J26 -> 0.01625 | M26: Semi Finished Item
A27: SF20600004 | B27: SF2013 | D27: =VLOOKUP(B27, 'RM & SF'!B:C, 2, 0) -> لحمة مجرمشة | E27: WH11140010 | F27: 4500 | G27: =VLOOKUP(F27, 'RM & SF'!B:C, 2, 0) -> فلفل حلو اخضر***** | H27: 50 | I27: =VLOOKUP(F27, 'RM & SF'!B:H, 4, 0) -> غم | J27: =H27/1 -> 50 | K27: =VLOOKUP(F27, 'RM & SF'!B:H, 7, 0) -> 0.00078 | L27: =K27*J27 -> 0.039 | M27: Semi Finished Item
A28: SF20600004 | B28: SF2013 | D28: =VLOOKUP(B28, 'RM & SF'!B:C, 2, 0) -> لحمة مجرمشة | E28: اضافة اودو | F28: 4598 | G28: =VLOOKUP(F28, 'RM & SF'!B:C, 2, 0) -> لية خروف نية***** | H28: 30 | I28: =VLOOKUP(F28, 'RM & SF'!B:H, 4, 0) -> غم | J28: =H28/1 -> 30 | K28: =VLOOKUP(F28, 'RM & SF'!B:H, 7, 0) -> 0.005 | L28: =K28*J28 -> 0.15 | M28: Semi Finished Item
A29: SF20600004 | B29: SF2013 | D29: =VLOOKUP(B29, 'RM & SF'!B:C, 2, 0) -> لحمة مجرمشة | E29: WH11060020 | F29: 4204 | G29: =VLOOKUP(F29, 'RM & SF'!B:C, 2, 0) -> فلفل اسود ناعم***** | H29: 3 | I29: =VLOOKUP(F29, 'RM & SF'!B:H, 4, 0) -> غم | J29: =H29/1 -> 3 | K29: =VLOOKUP(F29, 'RM & SF'!B:H, 7, 0) -> 0.006897 | L29: =K29*J29 -> 0.020691 | M29: Semi Finished Item
A30: SF20600004 | B30: SF2013 | D30: =VLOOKUP(B30, 'RM & SF'!B:C, 2, 0) -> لحمة مجرمشة | E30: WH11060003 | F30: 4152 | G30: =VLOOKUP(F30, 'RM & SF'!B:C, 2, 0) -> ملح طعام 750غم***** | H30: 3 | I30: =VLOOKUP(F30, 'RM & SF'!B:H, 4, 0) -> غم | J30: =H30/1 -> 3 | K30: =VLOOKUP(F30, 'RM & SF'!B:H, 7, 0) -> 0.00017066667 | L30: =K30*J30 -> 0.000512 | M30: Semi Finished Item
A31: SF20400008 | B31: SF963 | D31: =VLOOKUP(B31, 'RM & SF'!B:C, 2, 0) -> لحمة صفيحة ببندورة | E31: FPW3000042 | F31: 4601 | G31: =VLOOKUP(F31, 'RM & SF'!B:C, 2, 0) -> نتر خروف***** | H31: 400 | I31: =VLOOKUP(F31, 'RM & SF'!B:H, 4, 0) -> غم | J31: =H31/2.756 -> 145.13788 | K31: =VLOOKUP(F31, 'RM & SF'!B:H, 7, 0) -> 0.003 | L31: =K31*J31 -> 0.43541364 | M31: Semi Finished Item
A32: SF20400008 | B32: SF963 | D32: =VLOOKUP(B32, 'RM & SF'!B:C, 2, 0) -> لحمة صفيحة ببندورة | E32: اضافة اودو | F32: 5373 | G32: =VLOOKUP(F32, 'RM & SF'!B:C, 2, 0) -> قطعيات عجل مشكلة | H32: 600 | I32: =VLOOKUP(F32, 'RM & SF'!B:H, 4, 0) -> غم | J32: =H32/2.756 -> 217.70682 | K32: =VLOOKUP(F32, 'RM & SF'!B:H, 7, 0) -> 0.00901 | L32: =K32*J32 -> 1.9615385 | M32: Semi Finished Item
A33: SF20400008 | B33: SF963 | D33: =VLOOKUP(B33, 'RM & SF'!B:C, 2, 0) -> لحمة صفيحة ببندورة | E33: WH11140001 | F33: 4491 | G33: =VLOOKUP(F33, 'RM & SF'!B:C, 2, 0) -> بندورة جامدة***** | H33: 1000 | I33: =VLOOKUP(F33, 'RM & SF'!B:H, 4, 0) -> غم | J33: =H33/2.756 -> 362.8447 | K33: =VLOOKUP(F33, 'RM & SF'!B:H, 7, 0) -> 0.0005 | L33: =K33*J33 -> 0.18142235 | M33: Semi Finished Item
A34: SF20400008 | B34: SF963 | D34: =VLOOKUP(B34, 'RM & SF'!B:C, 2, 0) -> لحمة صفيحة ببندورة | E34: WH11140013 | F34: 4503 | G34: =VLOOKUP(F34, 'RM & SF'!B:C, 2, 0) -> بصل ناشف دفش***** | H34: 500 | I34: =VLOOKUP(F34, 'RM & SF'!B:H, 4, 0) -> غم | J34: =H34/2.756 -> 181.42235 | K34: =VLOOKUP(F34, 'RM & SF'!B:H, 7, 0) -> 0.00025 | L34: =K34*J34 -> 0.045355588 | M34: Semi Finished Item
A35: SF20400008 | B35: SF963 | D35: =VLOOKUP(B35, 'RM & SF'!B:C, 2, 0) -> لحمة صفيحة ببندورة | E35: WH11140011 | F35: 4501 | G35: =VLOOKUP(F35, 'RM & SF'!B:C, 2, 0) -> فلفل حلو احمر***** | H35: 100 | I35: =VLOOKUP(F35, 'RM & SF'!B:H, 4, 0) -> غم | J35: =H35/2.756 -> 36.28447 | K35: =VLOOKUP(F35, 'RM & SF'!B:H, 7, 0) -> 0.00075 | L35: =K35*J35 -> 0.027213353 | M35: Semi Finished Item
A36: SF20400008 | B36: SF963 | D36: =VLOOKUP(B36, 'RM & SF'!B:C, 2, 0) -> لحمة صفيحة ببندورة | E36: WH11250008 | F36: 4006 | G36: =VLOOKUP(F36, 'RM & SF'!B:C, 2, 0) -> دبس رمان 5 كغ (مادة أولية)***** | H36: 100 | I36: =VLOOKUP(F36, 'RM & SF'!B:H, 4, 0) -> غم | J36: =H36/2.756 -> 36.28447 | K36: =VLOOKUP(F36, 'RM & SF'!B:H, 7, 0) -> 0.001508 | L36: =K36*J36 -> 0.054716981 | M36: Semi Finished Item
A37: SF20400008 | B37: SF963 | D37: =VLOOKUP(B37, 'RM & SF'!B:C, 2, 0) -> لحمة صفيحة ببندورة | E37: WH11060019 | F37: 4211 | G37: =VLOOKUP(F37, 'RM & SF'!B:C, 2, 0) -> كزبرة ناعمة***** | H37: 10 | I37: =VLOOKUP(F37, 'RM & SF'!B:H, 4, 0) -> غم | J37: =H37/2.756 -> 3.628447 | K37: =VLOOKUP(F37, 'RM & SF'!B:H, 7, 0) -> 0.001509 | L37: =K37*J37 -> 0.0054753266 | M37: Semi Finished Item
A38: SF20400008 | B38: SF963 | D38: =VLOOKUP(B38, 'RM & SF'!B:C, 2, 0) -> لحمة صفيحة ببندورة | E38: WH11060030 | F38: 4218 | G38: =VLOOKUP(F38, 'RM & SF'!B:C, 2, 0) -> بهارات مشكلة***** | H38: 10 | I38: =VLOOKUP(F38, 'RM & SF'!B:H, 4, 0) -> غم | J38: =H38/2.756 -> 3.628447 | K38: =VLOOKUP(F38, 'RM & SF'!B:H, 7, 0) -> 0.003017 | L38: =K38*J38 -> 0.010947025 | M38: Semi Finished Item
A39: SF20400008 | B39: SF963 | D39: =VLOOKUP(B39, 'RM & SF'!B:C, 2, 0) -> لحمة صفيحة ببندورة | E39: WH11060020 | F39: 4204 | G39: =VLOOKUP(F39, 'RM & SF'!B:C, 2, 0) -> فلفل اسود ناعم***** | H39: 6 | I39: =VLOOKUP(F39, 'RM & SF'!B:H, 4, 0) -> غم | J39: =H39/2.756 -> 2.1770682 | K39: =VLOOKUP(F39, 'RM & SF'!B:H, 7, 0) -> 0.006897 | L39: =K39*J39 -> 0.015015239 | M39: Semi Finished Item
A40: SF20400008 | B40: SF963 | D40: =VLOOKUP(B40, 'RM & SF'!B:C, 2, 0) -> لحمة صفيحة ببندورة | E40: WH11060003 | F40: 4152 | G40: =VLOOKUP(F40, 'RM & SF'!B:C, 2, 0) -> ملح طعام 750غم***** | H40: 30 | I40: =VLOOKUP(F40, 'RM & SF'!B:H, 4, 0) -> غم | J40: =H40/2.756 -> 10.885341 | K40: =VLOOKUP(F40, 'RM & SF'!B:H, 7, 0) -> 0.00017066667 | L40: =K40*J40 -> 0.0018577649 | M40: Semi Finished Item
...

Sheet تفصيل فخد برازيلي
A1: كود الصنف | B1: اسم الصنف | C1: الكمية | D1: السعر | E1: الاجمالي | F1: الوزن صافي | G1: الفاقد | H1: السعر الصافي
A2: 5433 | B2: خروف مستورد | C2: 94.54 | D2: 7.25 | E2: =D2*C2 -> 685.415 | F2: 89.9 | G2: =C2-F2 -> 4.64 | H2: =E2/F2 -> 7.6241935

Sheet Finished Recipe
A1: odoo | B1: Menu Item New Code | D1: Menu Item Name | E1: Section | F1: Group Name | G1: odoo | H1: RM Item New Code | I1: Complete Item Description | J1: Unit | K1: Quantity | L1: Cost per Unit | M1: Total Cost | N1: Menu / SF Item | O1: Markaziya Price | P1: تكلفة الصنف | Q1: نسبة هامش الربح | R1: المواد الخام
A2: FP40100001 | B2: TA-ORD-001 | D2: =VLOOKUP(B2, 'All Menu'!B:M, 4, 0) -> منسف لحمة / كيلو | E2: =VLOOKUP(B2, 'All Menu'!B:M, 2, 0) -> قسم التواصي | F2: =VLOOKUP(B2, 'All Menu'!B:M, 3, 0) -> التواصي سفري | G2: اضافة اودو | H2: 4608 | I2: =VLOOKUP(H2, 'RM & SF'!B:H, 2, 0) -> لحمة قطع نية بالكيلو***** | J2: =VLOOKUP(H2, 'RM & SF'!B:E, 4, 0) -> غم | K2: 1000 | L2: =VLOOKUP(H2, 'RM & SF'!B:H, 7, 0) -> 0.011615493 | M2: =L2*K2 -> 11.615493 | N2: Menu Item | O2: =VLOOKUP(B2, 'All Menu'!B:L, 6, 0) -> 19.827586 | P2: =VLOOKUP(B2, 'All Menu'!B:L, 9, 0) -> 13.950858 | Q2: =VLOOKUP(B2, 'All Menu'!B:M, 12, 0) -> 0.29639153 | R2: =C2*K2 -> 0
A3: FP40100001 | B3: TA-ORD-001 | D3: =VLOOKUP(B3, 'All Menu'!B:M, 4, 0) -> منسف لحمة / كيلو | E3: =VLOOKUP(B3, 'All Menu'!B:M, 2, 0) -> قسم التواصي | F3: =VLOOKUP(B3, 'All Menu'!B:M, 3, 0) -> التواصي سفري | G3: SF20100003 | H3: SF2056 | I3: =VLOOKUP(H3, 'RM & SF'!B:H, 2, 0) -> ارز منسف | J3: =VLOOKUP(H3, 'RM & SF'!B:E, 4, 0) -> غم | K3: 1750 | L3: =VLOOKUP(H3, 'RM & SF'!B:H, 7, 0) -> 0.00049216375 | M3: =L3*K3 -> 0.86128656 | N3: Menu Item | O3: =VLOOKUP(B3, 'All Menu'!B:L, 6, 0) -> 19.827586 | P3: =VLOOKUP(B3, 'All Menu'!B:L, 9, 0) -> 13.950858 | Q3: =VLOOKUP(B3, 'All Menu'!B:M, 12, 0) -> 0.29639153 | R3: =C3*K3 -> 0
A4: FP40100001 | B4: TA-ORD-001 | D4: =VLOOKUP(B4, 'All Menu'!B:M, 4, 0) -> منسف لحمة / كيلو | E4: =VLOOKUP(B4, 'All Menu'!B:M, 2, 0) -> قسم التواصي | F4: =VLOOKUP(B4, 'All Menu'!B:M, 3, 0) -> التواصي سفري | G4: SF20100004 | H4: SF30218 | I4: =VLOOKUP(H4, 'RM & SF'!B:H, 2, 0) -> لبن | J4: =VLOOKUP(H4, 'RM & SF'!B:E, 4, 0) -> غم | K4: 1000 | L4: =VLOOKUP(H4, 'RM & SF'!B:H, 7, 0) -> 0.00059114973 | M4: =L4*K4 -> 0.59114973 | N4: Menu Item | O4: =VLOOKUP(B4, 'All Menu'!B:L, 6, 0) -> 19.827586 | P4: =VLOOKUP(B4, 'All Menu'!B:L, 9, 0) -> 13.950858 | Q4: =VLOOKUP(B4, 'All Menu'!B:M, 12, 0) -> 0.29639153
A5: FP40100001 | B5: TA-ORD-001 | D5: =VLOOKUP(B5, 'All Menu'!B:M, 4, 0) -> منسف لحمة / كيلو | E5: =VLOOKUP(B5, 'All Menu'!B:M, 2, 0) -> قسم التواصي | F5: =VLOOKUP(B5, 'All Menu'!B:M, 3, 0) -> التواصي سفري | G5: اضافة اودو | H5: 4354 | I5: =VLOOKUP(H5, 'RM & SF'!B:H, 2, 0) -> سدر بلاستيك دائري 35 سم***** | J5: =VLOOKUP(H5, 'RM & SF'!B:E, 4, 0) -> قطعة | K5: 1 | L5: =VLOOKUP(H5, 'RM & SF'!B:H, 7, 0) -> 0.28017 | M5: =L5*K5 -> 0.28017 | N5: Menu Item | O5: =VLOOKUP(B5, 'All Menu'!B:L, 6, 0) -> 19.827586 | P5: =VLOOKUP(B5, 'All Menu'!B:L, 9, 0) -> 13.950858 | Q5: =VLOOKUP(B5, 'All Menu'!B:M, 12, 0) -> 0.29639153
A6: FP40100001 | B6: TA-ORD-001 | D6: =VLOOKUP(B6, 'All Menu'!B:M, 4, 0) -> منسف لحمة / كيلو | E6: =VLOOKUP(B6, 'All Menu'!B:M, 2, 0) -> قسم التواصي | F6: =VLOOKUP(B6, 'All Menu'!B:M, 3, 0) -> التواصي سفري | G6: SF20100005 | H6: SF2025005 | I6: =VLOOKUP(H6, 'RM & SF'!B:H, 2, 0) -> لوز مقلي | J6: =VLOOKUP(H6, 'RM & SF'!B:E, 4, 0) -> غم | K6: 80 | L6: =VLOOKUP(H6, 'RM & SF'!B:H, 7, 0) -> 0.0041352328 | M6: =L6*K6 -> 0.33081862 | N6: Menu Item | O6: =VLOOKUP(B6, 'All Menu'!B:L, 6, 0) -> 19.827586 | P6: =VLOOKUP(B6, 'All Menu'!B:L, 9, 0) -> 13.950858 | Q6: =VLOOKUP(B6, 'All Menu'!B:M, 12, 0) -> 0.29639153
A7: FP40100001 | B7: TA-ORD-001 | D7: =VLOOKUP(B7, 'All Menu'!B:M, 4, 0) -> منسف لحمة / كيلو | E7: =VLOOKUP(B7, 'All Menu'!B:M, 2, 0) -> قسم التواصي | F7: =VLOOKUP(B7, 'All Menu'!B:M, 3, 0) -> التواصي سفري | G7: WH11070003 | H7: 4115 | I7: =VLOOKUP(H7, 'RM & SF'!B:H, 2, 0) -> خبز شراك***** | J7: =VLOOKUP(H7, 'RM & SF'!B:E, 4, 0) -> قطعة | K7: 2 | L7: =VLOOKUP(H7, 'RM & SF'!B:H, 7, 0) -> 0.1 | M7: =L7*K7 -> 0.2 | N7: Menu Item | O7: =VLOOKUP(B7, 'All Menu'!B:L, 6, 0) -> 19.827586 | P7: =VLOOKUP(B7, 'All Menu'!B:L, 9, 0) -> 13.950858 | Q7: =VLOOKUP(B7, 'All Menu'!B:M, 12, 0) -> 0.29639153
A8: FP40100001 | B8: TA-ORD-001 | D8: =VLOOKUP(B8, 'All Menu'!B:M, 4, 0) -> منسف لحمة / كيلو | E8: =VLOOKUP(B8, 'All Menu'!B:M, 2, 0) -> قسم التواصي | F8: =VLOOKUP(B8, 'All Menu'!B:M, 3, 0) -> التواصي سفري | G8: اضافة اودو | H8: 4285 | I8: =VLOOKUP(H8, 'RM & SF'!B:H, 2, 0) -> علب بلاستيك مربع متصل 150 مل***** | J8: =VLOOKUP(H8, 'RM & SF'!B:E, 4, 0) -> قطعة | K8: 1 | L8: =VLOOKUP(H8, 'RM & SF'!B:H, 7, 0) -> 0.01494 | M8: =L8*K8 -> 0.01494 | N8: Menu Item | O8: =VLOOKUP(B8, 'All Menu'!B:L, 6, 0) -> 19.827586 | P8: =VLOOKUP(B8, 'All Menu'!B:L, 9, 0) -> 13.950858 | Q8: =VLOOKUP(B8, 'All Menu'!B:M, 12, 0) -> 0.29639153
A9: FP40100001 | B9: TA-ORD-001 | D9: =VLOOKUP(B9, 'All Menu'!B:M, 4, 0) -> منسف لحمة / كيلو | E9: =VLOOKUP(B9, 'All Menu'!B:M, 2, 0) -> قسم التواصي | F9: =VLOOKUP(B9, 'All Menu'!B:M, 3, 0) -> التواصي سفري | G9: WH12020022 | H9: 4323 | I9: =VLOOKUP(H9, 'RM & SF'!B:H, 2, 0) -> قصدير رول 45 سم*2كغ***** | J9: =VLOOKUP(H9, 'RM & SF'!B:E, 4, 0) -> غم | K9: 0.06 | L9: =VLOOKUP(H9, 'RM & SF'!B:H, 7, 0) -> 0.001724 | M9: =L9*K9 -> 0.00010344 | N9: Menu Item | O9: =VLOOKUP(B9, 'All Menu'!B:L, 6, 0) -> 19.827586 | P9: =VLOOKUP(B9, 'All Menu'!B:L, 9, 0) -> 13.950858 | Q9: =VLOOKUP(B9, 'All Menu'!B:M, 12, 0) -> 0.29639153
A10: FP40100001 | B10: TA-ORD-001 | D10: =VLOOKUP(B10, 'All Menu'!B:M, 4, 0) -> منسف لحمة / كيلو | E10: =VLOOKUP(B10, 'All Menu'!B:M, 2, 0) -> قسم التواصي | F10: =VLOOKUP(B10, 'All Menu'!B:M, 3, 0) -> التواصي سفري | G10: اضافة اودو | H10: 5378 | I10: =VLOOKUP(H10, 'RM & SF'!B:H, 2, 0) -> رول مركزية تواصي | J10: =VLOOKUP(H10, 'RM & SF'!B:E, 4, 0) -> غم | K10: 20 | L10: =VLOOKUP(H10, 'RM & SF'!B:H, 7, 0) -> 0.00275 | M10: =L10*K10 -> 0.055 | N10: Menu Item | O10: =VLOOKUP(B10, 'All Menu'!B:L, 6, 0) -> 19.827586 | P10: =VLOOKUP(B10, 'All Menu'!B:L, 9, 0) -> 13.950858 | Q10: =VLOOKUP(B10, 'All Menu'!B:M, 12, 0) -> 0.29639153
A11: FP40100001 | B11: TA-ORD-001 | D11: =VLOOKUP(B11, 'All Menu'!B:M, 4, 0) -> منسف لحمة / كيلو | E11: =VLOOKUP(B11, 'All Menu'!B:M, 2, 0) -> قسم التواصي | F11: =VLOOKUP(B11, 'All Menu'!B:M, 3, 0) -> التواصي سفري | G11: WH12020053 | H11: 4329 | I11: =VLOOKUP(H11, 'RM & SF'!B:H, 2, 0) -> ملاعق بلاستيك مع معقم مطبوع 1*500 حبة***** | J11: =VLOOKUP(H11, 'RM & SF'!B:E, 4, 0) -> قطعة | K11: 4 | L11: =VLOOKUP(H11, 'RM & SF'!B:H, 7, 0) -> 0.000474 | M11: =L11*K11 -> 0.001896 | N11: Menu Item | O11: =VLOOKUP(B11, 'All Menu'!B:L, 6, 0) -> 19.827586 | P11: =VLOOKUP(B11, 'All Menu'!B:L, 9, 0) -> 13.950858 | Q11: =VLOOKUP(B11, 'All Menu'!B:M, 12, 0) -> 0.29639153
A12: FP40100002 | B12: TA-ORD-002 | D12: =VLOOKUP(B12, 'All Menu'!B:M, 4, 0) -> قدرة لحم 1 كيلو | E12: =VLOOKUP(B12, 'All Menu'!B:M, 2, 0) -> قسم التواصي | F12: =VLOOKUP(B12, 'All Menu'!B:M, 3, 0) -> التواصي سفري | G12: SF20100006 | H12: SF2053 | I12: =VLOOKUP(H12, 'RM & SF'!B:H, 2, 0) -> رز قدرة | J12: =VLOOKUP(H12, 'RM & SF'!B:E, 4, 0) -> غم | K12: 2000 | L12: =VLOOKUP(H12, 'RM & SF'!B:H, 7, 0) -> 0.00049428738 | M12: =L12*K12 -> 0.98857475 | N12: Menu Item | O12: =VLOOKUP(B12, 'All Menu'!B:L, 6, 0) -> 19.827586 | P12: =VLOOKUP(B12, 'All Menu'!B:L, 9, 0) -> 13.757562 | Q12: =VLOOKUP(B12, 'All Menu'!B:M, 12, 0) -> 0.30614036 | R12: =C12*K12 -> 0
A13: FP40100002 | B13: TA-ORD-002 | D13: =VLOOKUP(B13, 'All Menu'!B:M, 4, 0) -> قدرة لحم 1 كيلو | E13: =VLOOKUP(B13, 'All Menu'!B:M, 2, 0) -> قسم التواصي | F13: =VLOOKUP(B13, 'All Menu'!B:M, 3, 0) -> التواصي سفري | G13: اضافة اودو | H13: 4608 | I13: =VLOOKUP(H13, 'RM & SF'!B:H, 2, 0) -> لحمة قطع نية بالكيلو***** | J13: =VLOOKUP(H13, 'RM & SF'!B:E, 4, 0) -> غم | K13: 1000 | L13: =VLOOKUP(H13, 'RM & SF'!B:H, 7, 0) -> 0.011615493 | M13: =L13*K13 -> 11.615493 | N13: Menu Item | O13: =VLOOKUP(B13, 'All Menu'!B:L, 6, 0) -> 19.827586 | P13: =VLOOKUP(B13, 'All Menu'!B:L, 9, 0) -> 13.757562 | Q13: =VLOOKUP(B13, 'All Menu'!B:M, 12, 0) -> 0.30614036 | R13: =C13*K13 -> 0
A14: FP40100002 | B14: TA-ORD-002 | D14: =VLOOKUP(B14, 'All Menu'!B:M, 4, 0) -> قدرة لحم 1 كيلو | E14: =VLOOKUP(B14, 'All Menu'!B:M, 2, 0) -> قسم التواصي | F14: =VLOOKUP(B14, 'All Menu'!B:M, 3, 0) -> التواصي سفري | G14: SF20100005 | H14: SF2025005 | I14: =VLOOKUP(H14, 'RM & SF'!B:H, 2, 0) -> لوز مقلي | J14: =VLOOKUP(H14, 'RM & SF'!B:E, 4, 0) -> غم | K14: 150 | L14: =VLOOKUP(H14, 'RM & SF'!B:H, 7, 0) -> 0.0041352328 | M14: =L14*K14 -> 0.62028491 | N14: Menu Item | O14: =VLOOKUP(B14, 'All Menu'!B:L, 6, 0) -> 19.827586 | P14: =VLOOKUP(B14, 'All Menu'!B:L, 9, 0) -> 13.757562 | Q14: =VLOOKUP(B14, 'All Menu'!B:M, 12, 0) -> 0.30614036 | R14: =C14*K14 -> 0
A15: FP40100002 | B15: TA-ORD-002 | D15: =VLOOKUP(B15, 'All Menu'!B:M, 4, 0) -> قدرة لحم 1 كيلو | E15: =VLOOKUP(B15, 'All Menu'!B:M, 2, 0) -> قسم التواصي | F15: =VLOOKUP(B15, 'All Menu'!B:M, 3, 0) -> التواصي سفري | G15: SF20200001 | H15: SF4046 | I15: =VLOOKUP(H15, 'RM & SF'!B:H, 2, 0) -> خيار بلبن | J15: =VLOOKUP(H15, 'RM & SF'!B:E, 4, 0) -> غم | K15: 250 | L15: =VLOOKUP(H15, 'RM & SF'!B:H, 7, 0) -> 0.0010121558 | M15: =L15*K15 -> 0.25303895 | N15: Menu Item | O15: =VLOOKUP(B15, 'All Menu'!B:L, 6, 0) -> 19.827586 | P15: =VLOOKUP(B15, 'All Menu'!B:L, 9, 0) -> 13.757562 | Q15: =VLOOKUP(B15, 'All Menu'!B:M, 12, 0) -> 0.30614036 | R15: =C15*K15 -> 0
A16: FP40100002 | B16: TA-ORD-002 | D16: =VLOOKUP(B16, 'All Menu'!B:M, 4, 0) -> قدرة لحم 1 كيلو | E16: =VLOOKUP(B16, 'All Menu'!B:M, 2, 0) -> قسم التواصي | F16: =VLOOKUP(B16, 'All Menu'!B:M, 3, 0) -> التواصي سفري | G16: اضافة اودو | H16: 4354 | I16: =VLOOKUP(H16, 'RM & SF'!B:H, 2, 0) -> سدر بلاستيك دائري 35 سم***** | J16: =VLOOKUP(H16, 'RM & SF'!B:E, 4, 0) -> قطعة | K16: 1 | L16: =VLOOKUP(H16, 'RM & SF'!B:H, 7, 0) -> 0.28017 | M16: =L16*K16 -> 0.28017 | N16: Menu Item | O16: =VLOOKUP(B16, 'All Menu'!B:L, 6, 0) -> 19.827586 | P16: =VLOOKUP(B16, 'All Menu'!B:L, 9, 0) -> 13.757562 | Q16: =VLOOKUP(B16, 'All Menu'!B:M, 12, 0) -> 0.30614036 | R16: =C16*K16 -> 0
A17: FP40100007 | B17: TA-ORD-010 | D17: =VLOOKUP(B17, 'All Menu'!B:M, 4, 0) -> زرب لحم 1 كيلو | E17: =VLOOKUP(B17, 'All Menu'!B:M, 2, 0) -> قسم التواصي | F17: =VLOOKUP(B17, 'All Menu'!B:M, 3, 0) -> التواصي سفري | G17: SF20100007 | H17: SF2059 | I17: =VLOOKUP(H17, 'RM & SF'!B:H, 2, 0) -> ارز زرب | J17: =VLOOKUP(H17, 'RM & SF'!B:E, 4, 0) -> غم | K17: 2000 | L17: =VLOOKUP(H17, 'RM & SF'!B:H, 7, 0) -> 0.00051539514 | M17: =L17*K17 -> 1.0307903 | N17: Menu Item | O17: =VLOOKUP(B17, 'All Menu'!B:L, 6, 0) -> 19.827586 | P17: =VLOOKUP(B17, 'All Menu'!B:L, 9, 0) -> 13.546738 | Q17: =VLOOKUP(B17, 'All Menu'!B:M, 12, 0) -> 0.3167732 | R17: =C17*K17 -> 0
A18: FP40100007 | B18: TA-ORD-010 | D18: =VLOOKUP(B18, 'All Menu'!B:M, 4, 0) -> زرب لحم 1 كيلو | E18: =VLOOKUP(B18, 'All Menu'!B:M, 2, 0) -> قسم التواصي | F18: =VLOOKUP(B18, 'All Menu'!B:M, 3, 0) -> التواصي سفري | G18: اضافة اودو | H18: 4608 | I18: =VLOOKUP(H18, 'RM & SF'!B:H, 2, 0) -> لحمة قطع نية بالكيلو***** | J18: =VLOOKUP(H18, 'RM & SF'!B:E, 4, 0) -> غم | K18: 1000 | L18: =VLOOKUP(H18, 'RM & SF'!B:H, 7, 0) -> 0.011615493 | M18: =L18*K18 -> 11.615493 | N18: Menu Item | O18: =VLOOKUP(B18, 'All Menu'!B:L, 6, 0) -> 19.827586 | P18: =VLOOKUP(B18, 'All Menu'!B:L, 9, 0) -> 13.546738 | Q18: =VLOOKUP(B18, 'All Menu'!B:M, 12, 0) -> 0.3167732 | R18: =C18*K18 -> 0
A19: FP40100007 | B19: TA-ORD-010 | D19: =VLOOKUP(B19, 'All Menu'!B:M, 4, 0) -> زرب لحم 1 كيلو | E19: =VLOOKUP(B19, 'All Menu'!B:M, 2, 0) -> قسم التواصي | F19: =VLOOKUP(B19, 'All Menu'!B:M, 3, 0) -> التواصي سفري | G19: SF20100005 | H19: SF2025005 | I19: =VLOOKUP(H19, 'RM & SF'!B:H, 2, 0) -> لوز مقلي | J19: =VLOOKUP(H19, 'RM & SF'!B:E, 4, 0) -> غم | K19: 150 | L19: =VLOOKUP(H19, 'RM & SF'!B:H, 7, 0) -> 0.0041352328 | M19: =L19*K19 -> 0.62028491 | N19: Menu Item | O19: =VLOOKUP(B19, 'All Menu'!B:L, 6, 0) -> 19.827586 | P19: =VLOOKUP(B19, 'All Menu'!B:L, 9, 0) -> 13.546738 | Q19: =VLOOKUP(B19, 'All Menu'!B:M, 12, 0) -> 0.3167732 | R19: =C19*K19 -> 0
A20: FP40100007 | B20: TA-ORD-010 | D20: =VLOOKUP(B20, 'All Menu'!B:M, 4, 0) -> زرب لحم 1 كيلو | E20: =VLOOKUP(B20, 'All Menu'!B:M, 2, 0) -> قسم التواصي | F20: =VLOOKUP(B20, 'All Menu'!B:M, 3, 0) -> التواصي سفري | G20: اضافة اودو | H20: 4354 | I20: =VLOOKUP(H20, 'RM & SF'!B:H, 2, 0) -> سدر بلاستيك دائري 35 سم***** | J20: =VLOOKUP(H20, 'RM & SF'!B:E, 4, 0) -> قطعة | K20: 1 | L20: =VLOOKUP(H20, 'RM & SF'!B:H, 7, 0) -> 0.28017 | M20: =L20*K20 -> 0.28017 | N20: Menu Item | O20: =VLOOKUP(B20, 'All Menu'!B:L, 6, 0) -> 19.827586 | P20: =VLOOKUP(B20, 'All Menu'!B:L, 9, 0) -> 13.546738 | Q20: =VLOOKUP(B20, 'All Menu'!B:M, 12, 0) -> 0.3167732 | R20: =C20*K20 -> 0
A21: FP40100008 | B21: TA-ORD-011 | D21: =VLOOKUP(B21, 'All Menu'!B:M, 4, 0) -> مندي لحم 1 كيلو | E21: =VLOOKUP(B21, 'All Menu'!B:M, 2, 0) -> قسم التواصي | F21: =VLOOKUP(B21, 'All Menu'!B:M, 3, 0) -> التواصي سفري | G21: SF20100008 | H21: SF2054 | I21: =VLOOKUP(H21, 'RM & SF'!B:H, 2, 0) -> مندي | J21: =VLOOKUP(H21, 'RM & SF'!B:E, 4, 0) -> غم | K21: 2000 | L21: =VLOOKUP(H21, 'RM & SF'!B:H, 7, 0) -> 0.00049271573 | M21: =L21*K21 -> 0.98543146 | N21: Menu Item | O21: =VLOOKUP(B21, 'All Menu'!B:L, 6, 0) -> 19.827586 | P21: =VLOOKUP(B21, 'All Menu'!B:L, 9, 0) -> 13.50138 | Q21: =VLOOKUP(B21, 'All Menu'!B:M, 12, 0) -> 0.31906086 | R21: =C21*K21 -> 0
